Workbook

Sheet TB @ 30 Sept 2025
A1: Hunt3X Corporation
A2: Trial Balance as at 30 September 2025 | B2: Debit | C2: Credit
A3: Cash | B3: 387216
A4: Accounts Receivable | B4: 37100
A5: Prepaid Rent | B5: =2200*9 -> 19800
A6: Inventory | B6: 84000
A7: Accounts Payable | C7: 23400
A8: Unearned Revenue | C8: 14500
A9: Long-term Debt | C9: 50000
A10: Share Capital - Ordinary Shares | C10: 200000
A11: Share Capital - Preference Shares (cumulative) | C11: 200000
A12: Retained Earnings (@ 31 Dec 2024) | C12: 5230
A13: Sales Revenue | C13: 212300
A14: Cost of Goods Sold | B14: =C13*0.38 -> 80674
A15: Rent Expense | B15: =2200*3 -> 6600
A16: Marketing Expense | B16: 13000
A17: Salaries Expense | B17: =7700*9 -> 69300
A18: General Admin Expense | B18: =860*9 -> 7740
B19: =SUM(B3:B18) -> 705430 | C19: =SUM(C3:C18) -> 705430 | D19: =B19-C19 -> 0
A20: NI | B20: =C13-SUM(B14:B18) -> 34986

Sheet Tutorial 2 Sol
A1: TUTORIAL 2 SOLUTION
A2: PART (1) | H2: PART (2) | N2: Part (3) | W2: PART (4)
A3: Accounting Equation Effects | H3: Journal Entries | K3: Debit | L3: Credit | N3: Trial Balance Worksheet | W3: Total Liabilities | X3: =D22 -> 116350
B4: Assets | C4: = | D4: Liabilities | E4: + | F4: Equity | N4: Account Name | O4: @ 30 September 2025 | Q4: Transactions (Sept - Dec) | T4: @ 31 Dec 2025 | W4: Total Assets | X4: =B22 -> 831396
A5: Balance @ 30 Sept 2025 | B5: =SUM('TB @ 30 Sept 2025'!B3:B6) -> 528116 | C5: =C4 -> = | D5: =SUM('TB @ 30 Sept 2025'!C7:C9) -> 87900 | E5: =E4 -> + | F5: =SUM('TB @ 30 Sept 2025'!C10:C18)-SUM('TB @ 30 Sept 2025'!B10:B18) -> 440216 | G5: =B5-D5-F5 -> 0 | H5: (a) | I5: ='TB @ 30 Sept 2025'!A3 -> Cash | K5: 250000 | O5: Debit | P5: Credit | Q5: Ref | R5: Debit | S5: Credit | T5: Debit | U5: Credit | W5: Debt Ratio | X5: =X3/X4 -> 0.13994534
A6: =H5 -> (a) | B6: =K5 -> 250000 | C6: =C5 -> = | E6: =E5 -> + | F6: =L6 -> 250000 | J6: ='TB @ 30 Sept 2025'!A10 -> Share Capital - Ordinary Shares | L6: =K5 -> 250000 | N6: ='TB @ 30 Sept 2025'!A3 -> Cash | O6: ='TB @ 30 Sept 2025'!B3 -> 387216 | Q6: =H5 -> (a) | R6: =K5 -> 250000 | T6: =O6+SUM(R6:R15)-SUM(S6:S15) -> 359516
A7: =H8 -> (b) | B7: =K8 -> 30000 | C7: =C6 -> = | D7: =L9 -> 30000 | E7: =E6 -> + | Q7: =H8 -> (b) | R7: =K8 -> 30000 | W7: Beginning Total Assets | X7: ='TB @ 31 Dec 2024'!B13 -> 473830
A8: =H11 -> (c) | B8: =K11 -> 65000 | C8: =C7 -> = | E8: =E7 -> + | H8: (b) | I8: Cash | K8: 30000 | Q8: =H11 -> (c) | S8: =L12 -> 65000
B9: =-L12 -> -65000 | C9: =C8 -> = | E9: =E8 -> + | J9: Short Term Notes Payable | L9: =K8 -> 30000 | Q9: =H14 -> (d) | R9: =K14 -> 35000 | W9: Net Profit | X9: =U30-(SUM(T31:T35)) -> 59816
A10: =H14 -> (d) | B10: =K14 -> 35000 | C10: =C8 -> = | E10: =E8 -> + | F10: =L16 -> 96000 | Q10: =H21 -> (e) | R10: =K21 -> 64300 | W10: Average Total Assets | X10: =(X4+X7)/2 -> 652613
B11: =K15 -> 61000 | H11: (c) | I11: Inventory | K11: 65000 | Q11: =H24 -> (f) | S11: =L25 -> 22300 | W11: Return on Assets | X11: =X9/X10 -> 0.091656158
B12: =-L19 -> -30720 | C12: =C10 -> = | E12: =E10 -> + | F12: =-K18 -> -30720 | J12: Cash | L12: =K11 -> 65000 | Q12: =H27 -> (g) | S12: =L28 -> 19200
A13: =H21 -> (e) | B13: =K21 -> 64300 | C13: =C12 -> = | E13: =E12 -> + | Q13: =H30 -> (h) | S13: =L31 -> 300000
B14: =-L22 -> -64300 | C14: =C13 -> = | E14: =E13 -> + | H14: (d) | I14: Cash | K14: 35000 | Q14: =H33 -> (i) | S14: =L34 -> 5500
A15: =H24 -> (f) | B15: =-L25 -> -22300 | C15: =C14 -> = | E15: =E14 -> + | F15: =-K24 -> -22300 | I15: Accounts Receivable | K15: =L16-K14 -> 61000 | Q15: =H36 -> (j) | R15: =K36 -> 5000
A16: =H27 -> (g) | B16: =-L28 -> -19200 | C16: =C15 -> = | D16: =-K27 -> -19200 | E16: =E15 -> + | J16: Sales Revenue | L16: 96000 | N16: ='TB @ 30 Sept 2025'!A4 -> Accounts Receivable | O16: ='TB @ 30 Sept 2025'!B4 -> 37100 | Q16: =H14 -> (d) | R16: =K15 -> 61000 | T16: =O16+SUM(R16:R17)-SUM(S16:S17) -> 33800
A17: =H30 -> (h) | B17: =K30 -> 300000 | C17: =C16 -> = | E17: =E16 -> + | Q17: =H21 -> (e) | S17: =L22 -> 64300
B18: =-L31 -> -300000 | C18: =C17 -> = | E18: =E17 -> + | I18: Cost of Goods Sold | K18: =L16*0.32 -> 30720 | N18: ='TB @ 30 Sept 2025'!A5 -> Prepaid Rent | O18: ='TB @ 30 Sept 2025'!B5 -> 19800 | T18: =O18+R18-S18 -> 19800
A19: =H33 -> (i) | B19: -5500 | C19: =C18 -> = | E19: =E18 -> + | F19: =-K33 -> -5500 | J19: Inventory | L19: =K18 -> 30720 | N19: ='TB @ 30 Sept 2025'!A6 -> Inventory | O19: ='TB @ 30 Sept 2025'!B6 -> 84000 | Q19: =H11 -> (c) | R19: =K11 -> 65000 | T19: =O19+SUM(R19:R20)-SUM(S19:S20) -> 118280
A20: =H36 -> (j) | B20: =K36 -> 5000 | C20: =C19 -> = | D20: =L37 -> 5000 | Q20: =H14 -> (d) | S20: =L19 -> 30720
A21: =H39 -> (k) | C21: =C20 -> = | D21: =L40 -> 12650 | F21: =-K39 -> -12650 | H21: (e) | I21: ='TB @ 30 Sept 2025'!A3 -> Cash | K21: 64300 | N21: Property Plant and Equipment (PPE) | O21: 0 | Q21: =H30 -> (h) | R21: =K30 -> 300000 | T21: =O21+R21-S21 -> 300000
A22: Balance @ 31 Dec 2025 | B22: =SUM(B5:B21) -> 831396 | C22: = | D22: =SUM(D5:D21) -> 116350 | E22: + | F22: =SUM(F5:F21) -> 715046 | J22: ='TB @ 30 Sept 2025'!A4 -> Accounts Receivable | L22: =K21 -> 64300 | N22: ='TB @ 30 Sept 2025'!A7 -> Accounts Payable | P22: ='TB @ 30 Sept 2025'!C7 -> 23400 | Q22: =H27 -> (g) | R22: =K27 -> 19200 | U22: =P22+SUM(S22:S23)-SUM(R22:R23) -> 16850
Q23: =H39 -> (k) | S23: =L40 -> 12650
A24: check | B24: =SUM(T6:T21) -> 831396 | D24: =SUM(U22:U26) -> 116350 | F24: =SUM(U27:U36)-SUM(T27:T36) -> 715046 | H24: (f) | I24: ='TB @ 30 Sept 2025'!A17 -> Salaries Expense | K24: 22300 | N24: ='TB @ 30 Sept 2025'!A8 -> Unearned Revenue | P24: ='TB @ 30 Sept 2025'!C8 -> 14500 | Q24: =H36 -> (j) | S24: =L37 -> 5000 | U24: =P24+S24-R24 -> 19500
B25: =B22-B24 -> 0 | D25: =D22-D24 -> 0 | F25: =F22-F24 -> 0 | J25: ='TB @ 30 Sept 2025'!A3 -> Cash | L25: =K24 -> 22300 | N25: Short Term Notes Payable | P25: 0 | Q25: =H8 -> (b) | S25: =L9 -> 30000 | U25: =P25+S25-R25 -> 30000
N26: ='TB @ 30 Sept 2025'!A9 -> Long-term Debt | P26: ='TB @ 30 Sept 2025'!C9 -> 50000 | U26: =P26+S26-R26 -> 50000
H27: (g) | I27: ='TB @ 30 Sept 2025'!A7 -> Accounts Payable | K27: 19200 | N27: ='TB @ 30 Sept 2025'!A10 -> Share Capital - Ordinary Shares | P27: ='TB @ 30 Sept 2025'!C10 -> 200000 | Q27: =Q6 -> (a) | S27: =L6 -> 250000 | U27: =P27+S27-R27 -> 450000
J28: ='TB @ 30 Sept 2025'!A3 -> Cash | L28: =K27 -> 19200 | N28: ='TB @ 30 Sept 2025'!A11 -> Share Capital - Preference Shares (cumulative) | P28: ='TB @ 30 Sept 2025'!C11 -> 200000 | U28: =P28+S28-R28 -> 200000
N29: ='TB @ 30 Sept 2025'!A12 -> Retained Earnings (@ 31 Dec 2024) | P29: ='TB @ 30 Sept 2025'!C12 -> 5230 | U29: =P29+S29-R29 -> 5230
H30: (h) | I30: =N21 -> Property Plant and Equipment (PPE) | K30: 300000 | N30: ='TB @ 30 Sept 2025'!A13 -> Sales Revenue | P30: ='TB @ 30 Sept 2025'!C13 -> 212300 | Q30: =Q16 -> (d) | S30: =L16 -> 96000 | U30: =P30+S30-R30 -> 308300
J31: Cash | L31: =K30 -> 300000 | N31: ='TB @ 30 Sept 2025'!A14 -> Cost of Goods Sold | O31: ='TB @ 30 Sept 2025'!B14 -> 80674 | Q31: =Q30 -> (d) | R31: =K18 -> 30720 | T31: =O31+R31-S31 -> 111394
N32: ='TB @ 30 Sept 2025'!A15 -> Rent Expense | O32: ='TB @ 30 Sept 2025'!B15 -> 6600 | T32: =O32+R32-S32 -> 6600
H33: (i) | I33: ='TB @ 30 Sept 2025'!A16 -> Marketing Expense | K33: 5500 | N33: ='TB @ 30 Sept 2025'!A16 -> Marketing Expense | O33: ='TB @ 30 Sept 2025'!B16 -> 13000 | Q33: =H33 -> (i) | R33: =K33 -> 5500 | T33: =O33+R33-S33 -> 18500
J34: Cash | L34: =K33 -> 5500 | N34: ='TB @ 30 Sept 2025'!A17 -> Salaries Expense | O34: ='TB @ 30 Sept 2025'!B17 -> 69300 | Q34: =H24 -> (f) | R34: =K24 -> 22300 | T34: =O34+R34-S34 -> 91600
N35: ='TB @ 30 Sept 2025'!A18 -> General Admin Expense | O35: ='TB @ 30 Sept 2025'!B18 -> 7740 | Q35: =H39 -> (k) | R35: =K39 -> 12650 | T35: =O35+R35-S35 -> 20390
H36: (j) | I36: Cash | K36: 5000
J37: Unearned Revenue | L37: =K36 -> 5000 | O37: =SUM(O6:O36) -> 705430 | P37: =SUM(P6:P36) -> 705430 | R37: =SUM(R6:R36) -> 900670 | S37: =SUM(S6:S36) -> 900670 | T37: =SUM(T6:T36) -> 1079880 | U37: =SUM(U6:U36) -> 1079880
H39: (k) | I39: ='TB @ 30 Sept 2025'!A18 -> General Admin Expense | K39: 12650
J40: Accounts Payable | L40: =K39 -> 12650
K41: =SUM(K4:K37) -> 888020 | L41: =SUM(L4:L37) -> 888020

Sheet Tutorial 3 Sol
A1: TUTORIAL 3 SOLUTION
A3: Adjusting / Correcting Journal Entries | D3: Debit | E3: Credit
A5: (a) | B5: Rent Expense | D5: ='TB @ 30 Sept 2025'!B15 -> 6600
C6: Prepaid Rent | E6: =D5 -> 6600
A8: (b) | B8: Unearned Revenue | D8: ='Tutorial 2 Sol'!P24/2 -> 7250
C9: Sales Revenue | E9: =D8 -> 7250
B11: Cost of Goods Sold | D11: 2540
C12: Inventory | E12: =D11 -> 2540
A14: (c) | B14: Interest Expense | D14: 2850
C15: Interest Payable | E15: =D14 -> 2850
A17: (d) | B17: Consulting Fees | D17: =450*4 -> 1800
C18: Consulting Fees Payable | E18: =D17 -> 1800
A20: (e) | B20: Depreciation Expense | D20: 8200
C21: Accumulated Depreciation - Equipment | E21: =D20 -> 8200
A23: (f) | B23: Prepaid Salaries | D23: 2200
C24: Salaries Expense | E24: =D23 -> 2200
A26: (g) | B26: Income Tax Expense | D26: 4200
C27: Taxes Payable | E27: =D26 -> 4200
D28: =SUM(D4:D27) -> 35640 | E28: =SUM(E4:E27) -> 35640

Sheet Tutorial 4 Sol
A1: TUTORIAL 4 SOLUTION
A2: PART (1) | J2: PART (4) | P2: PART (2)
A3: TB Worksheet | C3: Unadjusted Trial Balance @ 31 Dec 2025 | E3: Adjustments (from Tutorial 2) | H3: Adjusted Trial Balance @ 31 Dec 2024 | J3: Closing (from part 3) | M3: Post Closing Trial Balance @ 31 Dec 2024 | P3: Hunt3X Coporation | T3: =P3 -> Hunt3X Coporation | AC3: =T3 -> Hunt3X Coporation
C4: Debit | D4: Credit | E4: Ref | F4: Debit | G4: Credit | H4: Debit | I4: Credit | J4: Ref | K4: Debit | L4: Credit | M4: Debit | N4: Credit | P4: Statement of Profit & Loss | T4: Statement of Changes in Equity | AC4: Statement of Financial Position
A5: ='TB @ 30 Sept 2025'!A3 -> Cash | C5: ='Tutorial 2 Sol'!T6 -> 359516 | H5: =C5+F5-G5 -> 359516 | M5: =H5+K5-L5 -> 359516 | P5: For the Year Ended 31 December 2025 | T5: =P5 -> For the Year Ended 31 December 2025 | AC5: As at 31 December 2025
A6: ='TB @ 30 Sept 2025'!A4 -> Accounts Receivable | C6: ='Tutorial 2 Sol'!T16 -> 33800 | H6: =C6+F6-G6 -> 33800 | M6: =H6+K6-L6 -> 33800
A7: ='TB @ 30 Sept 2025'!A5 -> Prepaid Rent | C7: ='Tutorial 2 Sol'!T18 -> 19800 | E7: ='Tutorial 3 Sol'!A5 -> (a) | G7: ='Tutorial 3 Sol'!E6 -> 6600 | H7: =C7+F7-G7 -> 13200 | M7: =H7+K7-L7 -> 13200 | Q7: Sales Revenue | R7: =I22 -> 315550 | U7: Ordinary | W7: Preference | Y7: Retained | AA7: Total | AC7: Assets
A8: Prepaid Salaries | C8: 0 | E8: ='Tutorial 3 Sol'!A23 -> (f) | F8: ='Tutorial 3 Sol'!D23 -> 2200 | H8: =C8+F8-G8 -> 2200 | M8: =H8+K8-L8 -> 2200 | Q8: =A23 -> Cost of Goods Sold | R8: =-H23 -> -113934 | U8: Shares | W8: Shares | Y8: Earnings | AA8: Equity | AC8: Current Assets:
A9: ='TB @ 30 Sept 2025'!A6 -> Inventory | C9: ='Tutorial 2 Sol'!T19 -> 118280 | E9: ='Tutorial 3 Sol'!A8 -> (b) | G9: ='Tutorial 3 Sol'!E12 -> 2540 | H9: =C9+F9-G9 -> 115740 | M9: =H9+K9-L9 -> 115740 | P9: Gross Profit | R9: =SUM(R7:R8) -> 201616 | T9: Beginning Balance | U9: ='TB @ 30 Sept 2025'!C10 -> 200000 | W9: ='TB @ 30 Sept 2025'!C11 -> 200000 | Y9: =I21 -> 5230 | AA9: =SUM(U9:Y9) -> 405230 | AD9: =A5 -> Cash | AE9: =H5 -> 359516
A10: ='Tutorial 2 Sol'!N21 -> Property Plant and Equipment (PPE) | C10: ='Tutorial 2 Sol'!T21 -> 300000 | H10: =C10+F10-G10 -> 300000 | M10: =H10+K10-L10 -> 300000 | Q10: ='Tutorial 4 Sol'!A24 -> Rent Expense | R10: =-H24 -> -13200 | T10: Shares Issuance | U10: ='Tutorial 2 Sol'!S27 -> 250000 | AA10: =U10 -> 250000 | AD10: =A6 -> Accounts Receivable | AE10: =H6 -> 33800
A11: Accumulated Depreciation - Equipment | D11: 0 | E11: ='Tutorial 3 Sol'!A20 -> (e) | G11: ='Tutorial 3 Sol'!E21 -> 8200 | I11: =D11+G11-F11 -> 8200 | N11: =I11+L11-K11 -> 8200 | Q11: ='Tutorial 4 Sol'!A25 -> Marketing Expense | R11: =-H25 -> -18500 | T11: Net Income | Y11: =R20 -> 43076 | AA11: =SUM(U11:Y11) -> 43076 | AD11: =A7 -> Prepaid Rent | AE11: =H7 -> 13200
A12: ='TB @ 30 Sept 2025'!A7 -> Accounts Payable | D12: ='Tutorial 2 Sol'!U22 -> 16850 | I12: =D12+G12-F12 -> 16850 | N12: =I12+L12-K12 -> 16850 | Q12: ='Tutorial 4 Sol'!A26 -> Salaries Expense | R12: =-H26 -> -89400 | T12: Ending Balance | U12: =SUM(U9:U11) -> 450000 | W12: =SUM(W9:W11) -> 200000 | Y12: =SUM(Y9:Y11) -> 48306 | AA12: =SUM(AA9:AA11) -> 698306 | AD12: =A8 -> Prepaid Salaries | AE12: =H8 -> 2200
A13: Unearned Revenue | D13: ='Tutorial 2 Sol'!U24 -> 19500 | E13: ='Tutorial 3 Sol'!A8 -> (b) | F13: ='Tutorial 3 Sol'!D8 -> 7250 | I13: =D13+G13-F13 -> 12250 | N13: =I13+L13-K13 -> 12250 | Q13: ='Tutorial 4 Sol'!A27 -> General Admin Expense | R13: =-H27 -> -20390 | AD13: =A9 -> Inventory | AE13: =H9 -> 115740
A14: Consulting Fees Payable | D14: 0 | E14: ='Tutorial 3 Sol'!A17 -> (d) | G14: ='Tutorial 3 Sol'!E18 -> 1800 | I14: =D14+G14-F14 -> 1800 | N14: =I14+L14-K14 -> 1800 | Q14: ='Tutorial 4 Sol'!A28 -> Consulting Fees | R14: =-H28 -> -1800 | AD14: Total Current Assets | AE14: =SUM(AE9:AE13) -> 524456
A15: Interest Payable | D15: 0 | E15: =E30 -> (c) | G15: ='Tutorial 3 Sol'!E15 -> 2850 | I15: =D15+G15-F15 -> 2850 | N15: =I15+L15-K15 -> 2850 | Q15: ='Tutorial 4 Sol'!A29 -> Depreciation Expense | R15: =-H29 -> -8200 | AC15: Non-current Assets:
A16: Taxes Payable | D16: 0 | E16: ='Tutorial 3 Sol'!A26 -> (g) | G16: ='Tutorial 3 Sol'!E27 -> 4200 | I16: =D16+G16-F16 -> 4200 | N16: =I16+L16-K16 -> 4200 | P16: Operating Income | R16: =SUM(R9:R15) -> 50126 | AD16: Property, Plant & Equipment (PPE) | AE16: =H10-I11 -> 291800
A17: ='Tutorial 2 Sol'!N25 -> Short Term Notes Payable | D17: ='Tutorial 2 Sol'!U25 -> 30000 | I17: =D17+G17-F17 -> 30000 | N17: =I17+L17-K17 -> 30000 | Q17: =A30 -> Interest Expense | R17: =-H30 -> -2850 | AD17: Total Non-current Assets | AE17: =SUM(AE16:AE16) -> 291800
A18: ='TB @ 30 Sept 2025'!A9 -> Long-term Debt | D18: ='Tutorial 2 Sol'!U26 -> 50000 | I18: =D18+G18-F18 -> 50000 | N18: =I18+L18-K18 -> 50000 | P18: Profit Before Tax | R18: =SUM(R16:R17) -> 47276 | AC18: Total Assets | AE18: =AE17+AE14 -> 816256
A19: ='TB @ 30 Sept 2025'!A10 -> Share Capital - Ordinary Shares | D19: ='Tutorial 2 Sol'!U27 -> 450000 | I19: =D19+G19-F19 -> 450000 | N19: =I19+L19-K19 -> 450000 | Q19: =A31 -> Income Tax Expense | R19: =-H31 -> -4200
A20: ='TB @ 30 Sept 2025'!A11 -> Share Capital - Preference Shares (cumulative) | D20: ='Tutorial 2 Sol'!U28 -> 200000 | I20: =D20+G20-F20 -> 200000 | N20: =I20+L20-K20 -> 200000 | P20: Net Income | R20: =SUM(R18:R19) -> 43076 | AC20: Liabilities
A21: Retained Earnings | D21: ='Tutorial 2 Sol'!U29 -> 5230 | I21: =D21+G21-F21 -> 5230 | J21: Part 3 | L21: =D47 -> 43076 | N21: =I21+L21-K21 -> 48306 | AC21: Current Liabilities:
A22: ='TB @ 30 Sept 2025'!A13 -> Sales Revenue | D22: ='Tutorial 2 Sol'!U30 -> 308300 | E22: =E13 -> (b) | G22: =F13 -> 7250 | I22: =D22+G22-F22 -> 315550 | J22: Part 3 | K22: =C37 -> 315550 | N22: =I22+L22-K22 -> 0 | P22: Check NI balance with TB | R22: =I22-SUM(H23:H31) -> 43076 | AD22: =A12 -> Accounts Payable | AE22: =I12 -> 16850
A23: ='TB @ 30 Sept 2025'!A14 -> Cost of Goods Sold | C23: ='Tutorial 2 Sol'!T31 -> 111394 | E23: ='Tutorial 3 Sol'!A8 -> (b) | F23: ='Tutorial 3 Sol'!D11 -> 2540 | H23: =C23+F23-G23 -> 113934 | J23: Part 3 | L23: =D38 -> 113934 | M23: =H23+K23-L23 -> 0 | AD23: =A13 -> Unearned Revenue | AE23: =I13 -> 12250
A24: ='TB @ 30 Sept 2025'!A15 -> Rent Expense | C24: ='Tutorial 2 Sol'!T32 -> 6600 | E24: =E7 -> (a) | F24: =G7 -> 6600 | H24: =C24+F24-G24 -> 13200 | J24: Part 3 | L24: =D39 -> 13200 | M24: =H24+K24-L24 -> 0 | AD24: =A14 -> Consulting Fees Payable | AE24: =I14 -> 1800
A25: ='TB @ 30 Sept 2025'!A16 -> Marketing Expense | C25: ='Tutorial 2 Sol'!T33 -> 18500 | H25: =C25+F25-G25 -> 18500 | J25: Part 3 | L25: =D40 -> 18500 | M25: =H25+K25-L25 -> 0 | AD25: =A15 -> Interest Payable | AE25: =I15 -> 2850
A26: ='TB @ 30 Sept 2025'!A17 -> Salaries Expense | C26: ='Tutorial 2 Sol'!T34 -> 91600 | E26: ='Tutorial 3 Sol'!A23 -> (f) | G26: ='Tutorial 3 Sol'!E24 -> 2200 | H26: =C26+F26-G26 -> 89400 | J26: Part 3 | L26: =D41 -> 89400 | M26: =H26+K26-L26 -> 0 | AD26: =A16 -> Taxes Payable | AE26: =I16 -> 4200
A27: ='Tutorial 2 Sol'!N35 -> General Admin Expense | C27: ='Tutorial 2 Sol'!T35 -> 20390 | H27: =C27+F27-G27 -> 20390 | J27: Part 3 | L27: =D42 -> 20390 | M27: =H27+K27-L27 -> 0 | AD27: ST Notes Payable | AE27: =N17 -> 30000
A28: Consulting Fees | C28: 0 | E28: ='Tutorial 3 Sol'!A17 -> (d) | F28: ='Tutorial 3 Sol'!D17 -> 1800 | H28: =C28+F28-G28 -> 1800 | J28: Part 3 | L28: =D43 -> 1800 | M28: =H28+K28-L28 -> 0 | AD28: Total Current Liabilities | AE28: =SUM(AE22:AE27) -> 67950
A29: Depreciation Expense | C29: 0 | E29: ='Tutorial 3 Sol'!A20 -> (e) | F29: ='Tutorial 3 Sol'!D20 -> 8200 | H29: =C29+F29-G29 -> 8200 | J29: Part 3 | L29: =D44 -> 8200 | M29: =H29+K29-L29 -> 0 | AC29: Non-current Liabilities:
A30: Interest Expense | C30: 0 | E30: ='Tutorial 3 Sol'!A14 -> (c) | F30: ='Tutorial 3 Sol'!D14 -> 2850 | H30: =C30+F30-G30 -> 2850 | J30: Part 3 | L30: =D45 -> 2850 | M30: =H30+K30-L30 -> 0 | AD30: =A18 -> Long-term Debt | AE30: =I18 -> 50000
A31: Income Tax Expense | C31: 0 | E31: ='Tutorial 3 Sol'!A26 -> (g) | F31: ='Tutorial 3 Sol'!D26 -> 4200 | H31: =C31+F31-G31 -> 4200 | J31: Part 3 | L31: =D46 -> 4200 | M31: =H31+K31-L31 -> 0 | AC31: Total Liabilities | AE31: =AE28+AE30 -> 117950
C32: =SUM(C5:C31) -> 1079880 | D32: =SUM(D5:D31) -> 1079880 | F32: =SUM(F5:F31) -> 35640 | G32: =SUM(G5:G31) -> 35640 | H32: =SUM(H5:H31) -> 1096930 | I32: =SUM(I5:I31) -> 1096930 | K32: =SUM(K5:K31) -> 315550 | L32: =SUM(L5:L31) -> 315550 | M32: =SUM(M5:M31) -> 824456 | N32: =SUM(N5:N31) -> 824456 | AC32: Equity
D33: =C32-D32 -> 0 | I33: =H32-I32 -> 0 | N33: =M32-N32 -> 0 | AC33: =A19 -> Share Capital - Ordinary Shares | AE33: =U12 -> 450000
AC34: =A20 -> Share Capital - Preference Shares (cumulative) | AE34: =W12 -> 200000
A35: PART (3) | AC35: Retained Earnings | AE35: =Y12 -> 48306
A36: Closing Entries @ 31 December 2025 | AC36: Total Equity | AE36: =SUM(AE33:AE35) -> 698306
A37: =A22 -> Sales Revenue | C37: =I22 -> 315550 | AC37: Total Liabilities & Equity | AE37: =AE36+AE31 -> 816256
B38: =A23 -> Cost of Goods Sold | D38: =H23 -> 113934
B39: =A24 -> Rent Expense | D39: =H24 -> 13200
B40: =A25 -> Marketing Expense | D40: =H25 -> 18500
...

Sheet Tutorial 5 Sol
A1: TUTORIAL 5 SOLUTION
A3: (a) | B3: The office that Hunt3X rented on 1 July 2025 (refer to Tutorial 3 part (a)) was in fact for two years instead of 1 year.
B4: The correct amount of rent expense for 2025 should have been: | G4: =26400/24*6 -> 6600
B5: The incorrect amount of rent expense reported on the financial statement: | G5: =-'Tutorial 4 Sol'!R10 -> 13200
B6: Correction amount to rent expense | G6: =G4-G5 -> -6600
A8: Part (1) Correcting Journal Entry
A9: Prepaid Rent | C9: =-G6 -> 6600
B10: Rent Expense | D10: =-G6 -> 6600
A12: Part (2) Effect on Ratios
C13: From Tutorial 4 Part (5) | D13: Effect of Corrections | G13: CORRECTED
A14: (i) | B14: Net Profit Margin | C14: =C15/C16 -> 0.13651085 | G14: =G15/G16 -> 0.15742672
B15: Net Income | C15: ='Tutorial 4 Sol'!C53:D53 -> 43076 | D15: =D10 -> 6600 | E15: increase | G15: =C15+D15 -> 49676
B16: Net Sales | C16: ='Tutorial 4 Sol'!C54:D54 -> 315550 | G16: =C16+D16 -> 315550
A18: (ii) | B18: Return on Assets | C18: =C19/C22 -> 0.066780044 | G18: =G19/G22 -> 0.076619937
B19: Net Income | C19: ='Tutorial 4 Sol'!C57:D57 -> 43076 | D19: =D15 -> 6600 | E19: =E15 -> increase | G19: =C19+D19 -> 49676
B20: Beginning Total Assets | C20: ='Tutorial 4 Sol'!C58:D58 -> 473830 | G20: =C20+D20 -> 473830
B21: Ending Total Assets | C21: ='Tutorial 4 Sol'!C59:D59 -> 816256 | D21: =C9 -> 6600 | E21: prepaid rent increase | G21: =C21+D21 -> 822856
B22: Average Total Assets | C22: ='Tutorial 4 Sol'!C60:D60 -> 645043 | G22: =SUM(G20:G21)/2 -> 648343
A24: (iii) | B24: Debt Ratio | C24: =C25/C26 -> 0.14450123 | G24: =G25/G26 -> 0.14334221
B25: Total Liabilities | C25: ='Tutorial 4 Sol'!C63:D63 -> 117950 | G25: =C25 -> 117950
B26: Total Assets | C26: ='Tutorial 4 Sol'!C64:D64 -> 816256 | D26: =D21 -> 6600 | E26: =E21 -> prepaid rent increase | G26: =C26+D26 -> 822856
A28: The error caused expenses to be higher than they should have been, resulting in lower net income and total assets. Consequently, both the net profit margin and ROA were understated compared to what they would have been if rent expenses had been recorded correctly. For instance, the net profit margin should have been 0.157 instead of 0.137, and the ROA should have been 0.076 instead of 0.066. This omission makes Hunt3X’s financial performance appear worse than it actually is and is potentially misleading to users of its financial statements.
A30: (b) | B30: In an attempt to boost its revenues, Hunt3X had previously recorded a cash deposit it received from a customer in the amount of $9,000 into the “Sales Revenue” account. The cash deposit is refundable to the customer within a year.
A31: Part (1) Correcting Journal Entry
A32: Sales Revenue | C32: 9000
B33: Deposits | D33: =C32 -> 9000
A35: Part (2) Effect on Ratios
C36: =C13 -> From Tutorial 4 Part (5) | D36: Effect of Corrections | G36: CORRECTED
A37: (i) | B37: Net Profit Margin | C37: =C38/C39 -> 0.13651085 | G37: =G38/G39 -> 0.11115968
B38: Net Income | C38: =C15 -> 43076 | D38: =-C32 -> -9000 | E38: decrease | G38: =C38+D38 -> 34076
B39: Net Sales | C39: =C16 -> 315550 | D39: =D38 -> -9000 | E39: =E38 -> decrease | G39: =C39+D39 -> 306550
A41: (ii) | B41: Return on Assets | C41: =C42/C45 -> 0.066780044 | G41: =G42/G45 -> 0.052827486
B42: Net Income | C42: =C19 -> 43076 | D42: =D39 -> -9000 | E42: =E39 -> decrease | G42: =C42+D42 -> 34076
B43: Beginning Total Assets | C43: =C20 -> 473830 | G43: =C43+D43 -> 473830
B44: Ending Total Assets | C44: =C21 -> 816256 | G44: =C44+D44 -> 816256
B45: Average Total Assets | C45: =C22 -> 645043 | G45: =SUM(G43:G44)/2 -> 645043
A47: (iii) | B47: Debt Ratio | C47: =C48/C49 -> 0.14450123 | G47: =G48/G49 -> 0.15552719
B48: Total Liabilities | C48: =C25 -> 117950 | D48: =D33 -> 9000 | E48: increase | G48: =C48+D48 -> 126950
B49: Total Assets | C49: =C26 -> 816256 | G49: =C49+D49 -> 816256
A51: Hunt3X incorrectly inflated its sales revenue and, consequently, its net income, while also understating its liabilities. The company should have reported a net income of $34,076 instead of $43,076. Without the erroneous sales entry, Hunt3X would have reported a lower net profit margin and ROA, along with a higher debt ratio. This misstatement has made Hunt3X’s financial performance appear better than it truly is, thereby misleading users of its financial statements.
...

Sheet Tutorial 6 Sol
A1: TUTORIAL 6 SOLUTION
A3: PART (1)
B4: Accounts Receivables Aging Analysis
B5: Classification of Receivables | C5: Amount | D5: Estimated % Uncollectible | E5: Estimated Uncollectible
B6: Current | C6: 29050 | D6: 0.02 | E6: =C6*D6 -> 581
B7: 1-60 days past due | C7: 2800 | D7: 0.15 | E7: =C7*D7 -> 420
B8: 61-90 days past due | C8: 1600 | D8: 0.25 | E8: =C8*D8 -> 400
B9: Over 90 days past due | C9: 350 | D9: 0.4 | E9: =C9*D9 -> 140
B10: Total | C10: =SUM(C6:C9) -> 33800 | E10: =SUM(E6:E9) -> 1541
B12: Calculation of ECL
B13: Loss Allowance unadjusted balance at 31 Dec 2025 | D13: 0
B14: Loss Allowance target balance at 31 Dec 2025 (based on AR aging) | D14: =E10 -> 1541
B15: Expected Credit Loss for 2025 | D15: =D14-D13 -> 1541
B17: Journal Entry
B18: Expected Credit Loss | C18: =D15 -> 1541
B19: Loss Allowance | D19: =C18 -> 1541
A21: PART (2)
A22: (i) | B22: Net Income
B23: Net Income before ECL adjustment | C23: ='Tutorial 4 Sol'!R20 -> 43076
B24: =B18 -> Expected Credit Loss | C24: =-D15 -> -1541
B25: Net Income after ECL adjustment | C25: =SUM(C23:C24) -> 41535
A27: (ii) | B27: Receivables (net) | C27: Gross Receivables | D27: Loss Allowance | E27: Net Receivables
B28: Balance at 31 Dec 2025 before ECL adjustment | C28: =C10 -> 33800 | D28: =-D13 -> 0 | E28: =SUM(C28:D28) -> 33800
B29: ECL | D29: =-D15 -> -1541
B30: Balance at 31 Dec 2025 after ECL adjustment | C30: =SUM(C28:C29) -> 33800 | D30: =SUM(D28:D29) -> -1541 | E30: =SUM(C30:D30) -> 32259
A32: (iii) | B32: Total Assets
B33: Total Assets before ECL adjustment | C33: ='Tutorial 4 Sol'!AE18 -> 816256
B34: Net receivables before ECL adjustment | C34: =-E28 -> -33800
B35: Net receivables after ECL adjustment | C35: =E30 -> 32259
B36: Total Assets after ECL adjustment | C36: =SUM(C33:C35) -> 814715
A38: PART (3)
C39: 2025
B40: Revenue | C40: ='Tutorial 4 Sol'!R7 -> 315550
B41: Trade Receivable - Beginning | C41: ='TB @ 31 Dec 2024'!B4 -> 21700
B42: Trade Receivable - Ending | C42: =E30 -> 32259
B43: Average Receivables | C43: =SUM(C41:C42)/2 -> 26979.5
B44: Receivables Turnover Ratio | C44: =C40/C43 -> 11.695917
B45: Average Collection Period | C45: =365/C44 -> 31.207471
A47: PART (4)
A48: (i) | B48: Journal Entry
...

Sheet Tutorial 7 Part 1-3 Sol
A1: TUTORIAL 7 SOLUTION (Part 1 -3)
A2: PART (1)
B3: Unaudited Inventory Balance at 31 Dec 2025 | D3: ='Tutorial 4 Sol'!AE13 -> 115740
B4: Physical count of Inventory at 31 Dec 2025 | D4: 108620
B5: Inventory Shrinkage | D5: =D3-D4 -> 7120
B7: Journal entry to account for inventory shrinkage
B8: Cost of Goods Sold | C8: =D5 -> 7120
B9: Inventory | D9: =C8 -> 7120
A10: PART (2)
B11: Cost of Goods Sold (audited) | C11: =-M41 -> 121054
B12: Beginning Inventory | C12: ='TB @ 31 Dec 2024'!B5 -> 102000
B13: Ending Inventory (audited) | C13: =H43 -> 108620
B14: Average Inventory | C14: =SUM(C12:C13)/2 -> 105310
B15: Inventory Turnover | C15: =C11/C14 -> 1.1495015
B16: Days Sale in Inventory | C16: =365/C15 -> 317.52895
A18: PART (3)
B19: Average Collection Period (from Tutorial 6 part 3) | C19: ='Tutorial 6 Sol'!C45 -> 31.207471
B20: Operating Cycle | C20: =C16+C19 -> 348.73643
B22: Cost of Goods Sold | C22: =C11 -> 121054
B23: Increase in Inventory (End - Beg) | C23: =C13-C12 -> 6620
B24: Total Purchase | C24: =SUM(C22:C23) -> 127674
B25: Beginning Accounts Payable | C25: ='TB @ 31 Dec 2024'!C6 -> 18600
B26: Ending Accounts Payable | C26: =I46 -> 16850
B27: Average Accounts Payable | C27: =SUM(C25:C26)/2 -> 17725
B28: Number of Days' Purchases in Payable | C28: =365/(C24/C27) -> 50.673003
B30: Net Operating Cycle | C30: =C20-C28 -> 298.06342
A32: Hunt3X has an operating cycle of 348 days, indicating that it takes Hunt3Xon average 348 days from the point inventory is purchased to selling it and receiving cash from its customer. However, Hunt3XI must pay its suppliers in 51 days, resulting in a net operating cyle of 298 days. This means that Hunt3X might need to seek financing to fund its operations for the 298 days either through equity or debt financing.
A34: Supplementary Workings
A35: TB Worksheet (with audit adjustments) | K35: AUDITED FS (after adjustements by auditors)
C36: Adjusted Trial Balance @ 31 Dec 2025 | E36: Audit Entries (from Tutorial 6 and Tutorial 7 ) | H36: Post Audit Trial Balance @ 31 Dec 2025 | K36: Hunt3X Corporation | O36: =K36 -> Hunt3X Corporation | X36: =O36 -> Hunt3X Corporation
C37: Debit | D37: Credit | E37: Ref | F37: Debit | G37: Credit | H37: Debit | I37: Credit | K37: Statement of Profit & Loss | O37: Statement of Changes in Equity | X37: Statement of Financial Position
A38: ='Tutorial 4 Sol'!A5 -> Cash | C38: ='Tutorial 4 Sol'!H5 -> 359516 | H38: =C38+F38-G38 -> 359516 | K38: For the Year Ended 31 December 2025 | O38: =K38 -> For the Year Ended 31 December 2025 | X38: As at 31 December 2025
A39: ='Tutorial 4 Sol'!A6 -> Accounts Receivable | C39: ='Tutorial 4 Sol'!H6 -> 33800 | H39: =C39+F39-G39 -> 33800
A40: Loss Allowance | D40: 0 | E40: Tutorial 6 | G40: ='Tutorial 6 Sol'!D19 -> 1541 | I40: =D40+G40-F40 -> 1541 | L40: Sales Revenue | M40: =I56 -> 315550 | P40: Ordinary | R40: Preference | T40: Retained | V40: Total | X40: Assets
A41: ='Tutorial 4 Sol'!A7 -> Prepaid Rent | C41: ='Tutorial 4 Sol'!H7 -> 13200 | H41: =C41+F41-G41 -> 13200 | L41: =A57 -> Cost of Goods Sold | M41: =-H57 -> -121054 | P41: Shares | R41: Shares | T41: Earnings | V41: Equity | X41: Current Assets:
A42: ='Tutorial 4 Sol'!A8 -> Prepaid Salaries | C42: ='Tutorial 4 Sol'!H8 -> 2200 | H42: =C42+F42-G42 -> 2200 | K42: Gross Profit | M42: =SUM(M40:M41) -> 194496 | O42: Beginning Balance | P42: ='Tutorial 4 Sol'!U9 -> 200000 | R42: ='Tutorial 4 Sol'!W9 -> 200000 | T42: =D55 -> 5230 | V42: =SUM(P42:T42) -> 405230 | Y42: =A38 -> Cash | Z42: =C38 -> 359516
A43: ='Tutorial 4 Sol'!A9 -> Inventory | C43: ='Tutorial 4 Sol'!H9 -> 115740 | E43: Tutorial 7 | G43: =D9 -> 7120 | H43: =C43+F43-G43 -> 108620 | L43: =A58 -> Rent Expense | M43: =-H58 -> -13200 | O43: Shares Issuance | P43: ='Tutorial 4 Sol'!U10 -> 250000 | V43: =P43 -> 250000 | Y43: Accounts Receivable (net) | Z43: =H39-I40 -> 32259
A44: ='Tutorial 4 Sol'!A10 -> Property Plant and Equipment (PPE) | C44: ='Tutorial 4 Sol'!H10 -> 300000 | H44: =C44+F44-G44 -> 300000 | L44: =A59 -> Marketing Expense | M44: =-H59 -> -18500 | O44: Net Income | T44: =M54 -> 34415 | V44: =SUM(P44:T44) -> 34415 | Y44: =A41 -> Prepaid Rent | Z44: =H41 -> 13200
A45: ='Tutorial 4 Sol'!A11 -> Accumulated Depreciation - Equipment | D45: ='Tutorial 4 Sol'!I11 -> 8200 | I45: =D45+G45-F45 -> 8200 | L45: =A60 -> Salaries Expense | M45: =-H60 -> -89400 | O45: Ending Balance | P45: =SUM(P42:P44) -> 450000 | R45: =SUM(R42:R44) -> 200000 | T45: =SUM(T42:T44) -> 39645 | V45: =SUM(V42:V44) -> 689645 | Y45: =A42 -> Prepaid Salaries | Z45: =H42 -> 2200
A46: ='Tutorial 4 Sol'!A12 -> Accounts Payable | D46: ='Tutorial 4 Sol'!I12 -> 16850 | I46: =D46+G46-F46 -> 16850 | L46: =A61 -> General Admin Expense | M46: =-H61 -> -20390 | Y46: =A43 -> Inventory | Z46: =H43 -> 108620
...

Sheet Tutorial 7 Part 4&5 Sol
A1: TUTORIAL 7 SOLUTION (Part 4-5)
A3: Date | B3: Transaction | C3: Units | D3: Cost/Unit | E3: Total Cost
A4: 46023 | B4: Beginning Inventory | C4: 42 | D4: 960 | E4: =D4*C4 -> 40320
A5: 46030 | B5: Purchase | C5: 20 | D5: 880 | E5: =D5*C5 -> 17600
A6: 46033 | B6: Sales | C6: 39
A7: 46038 | B7: Purchase | C7: 30 | D7: 910 | E7: =D7*C7 -> 27300
A8: 46043 | B8: Sales | C8: 41
A9: 46046 | B9: Purchase | C9: 10 | D9: 1050 | E9: =D9*C9 -> 10500
B11: Beg Inventory | D11: =E4 -> 40320
B12: Purchases:
B13: =A5 -> 46030 | C13: =E5 -> 17600
B14: =A7 -> 46038 | C14: =E7 -> 27300
B15: =A9 -> 46046 | C15: =E9 -> 10500 | D15: =SUM(C13:C15) -> 55400
B16: Cost of Goods Available for Sale | D16: =SUM(D11:D15) -> 95720
B18: Units available for Sale | D18: =C4+C5+C7+C9 -> 102
B19: Units sold | D19: =-(C6+C8) -> -80
B20: Units available at end of period | D20: =SUM(D18:D19) -> 22
A22: PART (4) PERIODIC SYSTEM | G22: PART (5) PERPETUAL SYSTEM
A23: (i) | B23: FIFO | G23: (i) | H23: FIFO
B24: =B16 -> Cost of Goods Available for Sale | D24: =D16 -> 95720 | H24: =B24 -> Cost of Goods Available for Sale | M24: =D16 -> 95720
B25: Cost of Ending Inventory | H25: Cost of Ending Inventory
B26: 10 units (Batch of 24-Jan -26) | C26: =-C9*D9 -> -10500 | H26: =B26 -> 10 units (Batch of 24-Jan -26) | L26: =C26 -> -10500
B27: 12 units (Batch of 16-Jan -26) | C27: =-(D20-C9)*D7 -> -10920 | D27: =SUM(C26:C27) -> -21420 | H27: =B27 -> 12 units (Batch of 16-Jan -26) | L27: =C27 -> -10920 | M27: =SUM(L26:L27) -> -21420
B28: Cost of Goods Sold | D28: =SUM(D24:D27) -> 74300 | H28: Cost of Goods Sold | M28: =SUM(M24:M27) -> 74300
A30: (ii) | B30: Weighted Average Cost | G30: (ii) | H30: =B30 -> Weighted Average Cost
B31: =B24 -> Cost of Goods Available for Sale | D31: =D24 -> 95720 | H31: Date | I31: Beg Inv & Goods Purchased | L31: COGS | O31: Inventory Balance
B32: =B18 -> Units available for Sale | D32: =D18 -> 102 | I32: Unit | J32: Price | K32: Amount | L32: Unit | M32: Price | N32: Amount | O32: Unit | P32: Price | Q32: Amount
B33: Weighted average cost per unit | D33: =D31/D32 -> 938.43137 | H33: =A4 -> 46023 | I33: =C4 -> 42 | J33: =D4 -> 960 | K33: =I33*J33 -> 40320 | O33: =I33 -> 42 | P33: =J33 -> 960 | Q33: =O33*P33 -> 40320
B34: Units sold | D34: =-D19 -> 80 | H34: =A5 -> 46030 | I34: =C5 -> 20 | J34: =D5 -> 880 | K34: =I34*J34 -> 17600 | O34: =I34 -> 20 | P34: =J34 -> 880 | Q34: =O34*P34 -> 17600
B35: Ending Units | D35: =D32-D34 -> 22 | O35: =SUM(O33:O34) -> 62 | P35: =Q35/O35 -> 934.19355 | Q35: =SUM(Q33:Q34) -> 57920
B36: Cost of Ending Inventory | D36: =D35*D33 -> 20645.49 | H36: =A6 -> 46033 | L36: =C6 -> 39 | M36: =P35 -> 934.19355 | N36: =L36*M36 -> 36433.548 | O36: =O35-L36 -> 23 | P36: =M36 -> 934.19355 | Q36: =P36*O36 -> 21486.452
B37: Cost of Good Sold | D37: =D31-D36 -> 75074.51 | H37: =A7 -> 46038 | I37: =C7 -> 30 | J37: =D7 -> 910 | K37: =I37*J37 -> 27300 | O37: =I37 -> 30 | P37: =J37 -> 910 | Q37: =O37*P37 -> 27300
O38: =SUM(O36:O37) -> 53 | P38: =Q38/O38 -> 920.49909 | Q38: =SUM(Q36:Q37) -> 48786.452
A39: (iii) | B39: LIFO | H39: =A8 -> 46043 | L39: =C8 -> 41 | M39: =P38 -> 920.49909 | N39: =L39*M39 -> 37740.463 | O39: =O38-L39 -> 12 | P39: =M39 -> 920.49909 | Q39: =P39*O39 -> 11045.989
B40: =B31 -> Cost of Goods Available for Sale | D40: =D16 -> 95720 | H40: =A9 -> 46046 | I40: =C9 -> 10 | J40: =D9 -> 1050 | K40: =I40*J40 -> 10500 | O40: =I40 -> 10 | P40: =J40 -> 1050 | Q40: =O40*P40 -> 10500
B41: Cost of Ending Inventory | H41: Total | I41: =SUM(I33:I40) -> 102 | K41: =SUM(K33:K40) -> 95720 | L41: =SUM(L36:L40) -> 80 | N41: =SUM(N36:N40) -> 74174.011 | O41: =I41-L41 -> 22 | P41: =Q41/O41 -> 979.36314 | Q41: =SUM(Q39:Q40) -> 21545.989
B42: 22 units (Batch of 1-Jan-25) | D42: =-D20*D4 -> -21120
B43: Cost of Goods Sold | D43: =SUM(D40:D42) -> 74600

Sheet Tutorial 8 Sol
A1: TUTORIAL 8 SOLUTION
A3: Part (1) Warranty:
A4: (i) | B4: Q3 Sales | F4: 24800
B5: Warranty Expense Rate | F5: 0.02
B6: Q3 Warranty Expense | F6: =F4*F5 -> 496
B8: Q4 Sales | F8: 56200
B9: Warranty Expense Rate | F9: 0.02
B10: Q4 Warranty Expense | F10: =F8*F9 -> 1124
B12: Warranty Provision account:
C13: Beg Balance (1 July 2026) | F13: 0
C14: Q3 Warranty Expense | F14: =F6 -> 496
C15: Balance at end of Q3 | F15: =SUM(F13:F14) -> 496
C16: Q4 Warranty Used | F16: -275
C17: Q4 Warranty Expense | F17: =F10 -> 1124
C18: Balance at end of Q4 | F18: =SUM(F15:F17) -> 1345
A20: (ii) | B20: If actual warranty claims consistently fall below the original estimate (e.g., 1% instead of 2%), Hunt3X should consider revising its provision rate downward to better reflect its operations. Reducing the estimate would lower the warranty expense recognized in the Income Statement, thereby increasing reported net income. However, since Hunt3X is a relatively new company without an established track record, management may choose to remain conservative and maintain a slightly higher estimate until more years of historical data are available. Exercising prudence helps avoid understating potential liabilities. Ultimately, if management is confident that the lower rate reflects the best current estimate, it would be appropriate to revise the provision rate.
A22: (iii) | B22: Cash | E22: 4460
C23: Unearned Revenue - Extended Warranties | F23: 4460
B25: The accounting manager should explain to the CEO that under the revenue recognition principle, revenue is recognized only when performance obligations are satisfied. Therefore in this case, over the one-year extended warranty period. Recognizing the full $4,460 in 2026 would overstate revenue and net income for that year and mislead users of the financial statements. The proper treatment is to recognize the revenue systematically over the extended warranty period when the original warranty expires and the extended warranty starts. For example, on a straight line basis starting in Q4 of 2027, which means that Hunt3X would recognize $1,115 of revenue in Q4 of 2027 and Q1, Q2 and Q3 of 2028 respectively.
A27: Part (2) Short Tem Notes
A28: (i) | B28: 14 Sept 2026 Journal Entry
B29: Cash | E29: 35000
C30: Notes Payable | F30: =E29 -> 35000
A32: (ii) | B32: 30 Sept 2026 Journal Entry
B33: Interest Expense | E33: =F42 -> 155.56
C34: Interest Payabe | F34: =E33 -> 155.56
A36: (ii) | B36: 31 Dec 2026 Journal Entry
B37: Interest Expense | E37: =F43 -> 894.44
C38: Interest Payabe | F38: =E37 -> 894.44
B40: Daily Interest (30k x 10% /360) | F40: =F30*10%/360 -> 9.7222222
B41: Total Interest on the note (120 days) | F41: =F40*120 -> 1166.6667
B42: Interest for Q3 (16 days) | F42: =ROUND(F40*16,2) -> 155.56
B43: Interest for Q4 (92 days) | F43: =ROUND((F40*(31+30+31)),2) -> 894.44
B44: 2026 Interest Expense | F44: =SUM(F42:F43) -> 1050
B45: 2027 Interest Expense | F45: =F40*12 -> 116.66667
A47: (iii) | B47: Date of Repayment: 12 January 2027
B48: =C30 -> Notes Payable | E48: =F30 -> 35000
B49: Interest Payable | E49: =SUM(F42:F43) -> 1050
B50: Interest Expense | E50: =F40*12 -> 116.66667
C51: Cash | F51: =SUM(E48:E50) -> 36166.667
...

Sheet TB @ 31 Dec 2024
A1: Hunt3X Corporation
A2: Account Balances as at 31 Dec 2024 | B2: Debit | C2: Credit
A3: ='TB @ 30 Sept 2025'!A3 -> Cash | B3: 350130
A4: ='TB @ 30 Sept 2025'!A4 -> Accounts Receivable | B4: 21700
A5: ='TB @ 30 Sept 2025'!A6 -> Inventory | B5: 102000
A6: ='TB @ 30 Sept 2025'!A7 -> Accounts Payable | C6: 18600
A7: ='TB @ 30 Sept 2025'!A9 -> Long-term Debt | C7: ='TB @ 30 Sept 2025'!C9 -> 50000
A8: ='TB @ 30 Sept 2025'!A10 -> Share Capital - Ordinary Shares | C8: ='TB @ 30 Sept 2025'!C10 -> 200000
A9: ='TB @ 30 Sept 2025'!A11 -> Share Capital - Preference Shares (cumulative) | C9: ='TB @ 30 Sept 2025'!C11 -> 200000
A10: ='TB @ 30 Sept 2025'!A12 -> Retained Earnings (@ 31 Dec 2024) | C10: ='TB @ 30 Sept 2025'!C12 -> 5230
B11: =SUM(B3:B10) -> 473830 | C11: =SUM(C3:C10) -> 473830 | D11: =B11-C11 -> 0
A13: Total Assets | B13: =SUM(B3:B5) -> 473830
A14: Total Liabilities | C14: =SUM(C6:C7) -> 68600
A15: Total Equity | C15: =SUM(C8:C10) -> 405230 | D15: =B13-C14-C15 -> 0
