Workbook

Sheet TB @ 30 Sept 2025
A1: Hunt3X Corporation
A2: Trial Balance as at 30 September 2025 | B2: Debit | C2: Credit
A3: Cash | B3: 387216
A4: Accounts Receivable | B4: 37100
A5: Prepaid Rent | B5: =2200*9 -> 19800
A6: Inventory | B6: 84000
A7: Accounts Payable | C7: 23400
A8: Unearned Revenue | C8: 14500
A9: Long-term Debt | C9: 50000
A10: Share Capital - Ordinary Shares | C10: 200000
A11: Share Capital - Preference Shares (cumulative) | C11: 200000
A12: Retained Earnings (@ 31 Dec 2024) | C12: 5230
A13: Sales Revenue | C13: 212300
A14: Cost of Goods Sold | B14: =C13*0.38 -> 80674
A15: Rent Expense | B15: =2200*3 -> 6600
A16: Marketing Expense | B16: 13000
A17: Salaries Expense | B17: =7700*9 -> 69300
A18: General Admin Expense | B18: =860*9 -> 7740
B19: =SUM(B3:B18) -> 705430 | C19: =SUM(C3:C18) -> 705430
A20: NI | B20: =C13-SUM(B14:B18) -> 34986

Sheet Tutorial 2 Sol
A1: TUTORIAL 2 SOLUTION
A2: PART (1) | H2: PART (2) | N2: Part (3) | W2: PART (4)
A3: Accounting Equation Effects | H3: Journal Entries | K3: Debit | L3: Credit | N3: Trial Balance Worksheet | W3: Total Liabilities | X3: =D22 -> 116350
B4: Assets | C4: = | D4: Liabilities | E4: + | F4: Equity | N4: Account Name | O4: @ 30 September 2025 | Q4: Transactions (Sept - Dec) | T4: @ 31 Dec 2025 | W4: Total Assets | X4: =B22 -> 831396
A5: Balance @ 30 Sept 2025 | B5: =SUM('TB @ 30 Sept 2025'!B3:B6) -> 528116 | C5: =C4 -> = | D5: =SUM('TB @ 30 Sept 2025'!C7:C9) -> 87900 | E5: =E4 -> + | F5: =SUM('TB @ 30 Sept 2025'!C10:C18)-SUM('TB @ 30 Sept 2025'!B10:B18) -> 440216 | G5: =B5-D5-F5 -> 0 | H5: (a) | I5: Cash | K5: 250000 | O5: Debit | P5: Credit | Q5: Ref | R5: Debit | S5: Credit | T5: Debit | U5: Credit | W5: Debt Ratio | X5: =X3/X4 -> 0.13994534
A6: =H5 -> (a) | B6: =K5 -> 250000 | C6: =C5 -> = | E6: =E5 -> + | F6: =L6 -> 250000 | J6: Share Capital - Ordinary Shares | L6: =K5 -> 250000 | N6: ='TB @ 30 Sept 2025'!A3 -> Cash | O6: ='TB @ 30 Sept 2025'!B3 -> 387216 | Q6: =H5 -> (a) | R6: =K5 -> 250000 | T6: =O6+SUM(R6:R15)-SUM(S6:S15) -> 359516
A7: =H8 -> (b) | B7: =K8 -> 30000 | C7: =C6 -> = | D7: =L9 -> 30000 | E7: =E6 -> + | Q7: =H8 -> (b) | R7: =K8 -> 30000 | W7: Beginning Total Assets | X7: ='TB @ 31 Dec 2024'!B13 -> 473830
A8: =H11 -> (c) | B8: =K11 -> 65000 | C8: =C7 -> = | E8: =E7 -> + | H8: (b) | I8: Cash | K8: 30000 | Q8: =H11 -> (c) | S8: =L12 -> 65000
B9: =-L12 -> -65000 | C9: =C8 -> = | E9: =E8 -> + | J9: Short Term Notes Payable | L9: =K8 -> 30000 | Q9: =H14 -> (d) | R9: =K14 -> 35000 | W9: Net Profit | X9: =U30-(SUM(T31:T35)) -> 59816
A10: =H14 -> (d) | B10: =K14 -> 35000 | C10: =C8 -> = | E10: =E8 -> + | F10: =L16 -> 96000 | Q10: =H21 -> (e) | R10: =K21 -> 64300 | W10: Average Total Assets | X10: =(X4+X7)/2 -> 652613
B11: =K15 -> 61000 | H11: (c) | I11: Inventory | K11: 65000 | Q11: =H24 -> (f) | S11: =L25 -> 22300 | W11: Return on Assets | X11: =X9/X10 -> 0.091656158
B12: =-L19 -> -30720 | C12: =C10 -> = | E12: =E10 -> + | F12: =-K18 -> -30720 | J12: Cash | L12: =K11 -> 65000 | Q12: =H27 -> (g) | S12: =L28 -> 19200
A13: =H21 -> (e) | B13: =K21 -> 64300 | C13: =C12 -> = | E13: =E12 -> + | Q13: =H30 -> (h) | S13: =L31 -> 300000
B14: =-L22 -> -64300 | C14: =C13 -> = | E14: =E13 -> + | H14: (d) | I14: Cash | K14: 35000 | Q14: =H33 -> (i) | S14: =L34 -> 5500
A15: =H24 -> (f) | B15: =-L25 -> -22300 | C15: =C14 -> = | E15: =E14 -> + | F15: =-K24 -> -22300 | I15: Accounts Receivable | K15: =L16-K14 -> 61000 | Q15: =H36 -> (j) | R15: =K36 -> 5000
A16: =H27 -> (g) | B16: =-L28 -> -19200 | C16: =C15 -> = | D16: =-K27 -> -19200 | E16: =E15 -> + | J16: Sales Revenue | L16: 96000 | N16: ='TB @ 30 Sept 2025'!A4 -> Accounts Receivable | O16: ='TB @ 30 Sept 2025'!B4 -> 37100 | Q16: =H14 -> (d) | R16: =K15 -> 61000 | T16: =O16+SUM(R16:R17)-SUM(S16:S17) -> 33800
A17: =H30 -> (h) | B17: =K30 -> 300000 | C17: =C16 -> = | E17: =E16 -> + | Q17: =H21 -> (e) | S17: =L22 -> 64300
B18: =-L31 -> -300000 | C18: =C17 -> = | E18: =E17 -> + | I18: Cost of Goods Sold | K18: =L16*0.32 -> 30720 | N18: ='TB @ 30 Sept 2025'!A5 -> Prepaid Rent | O18: ='TB @ 30 Sept 2025'!B5 -> 19800 | T18: =O18+R18-S18 -> 19800
A19: =H33 -> (i) | B19: -5500 | C19: =C18 -> = | E19: =E18 -> + | F19: =-K33 -> -5500 | J19: Inventory | L19: =K18 -> 30720 | N19: ='TB @ 30 Sept 2025'!A6 -> Inventory | O19: ='TB @ 30 Sept 2025'!B6 -> 84000 | Q19: =H11 -> (c) | R19: =K11 -> 65000 | T19: =O19+SUM(R19:R20)-SUM(S19:S20) -> 118280
A20: =H36 -> (j) | B20: =K36 -> 5000 | C20: =C19 -> = | D20: =L37 -> 5000 | Q20: =H14 -> (d) | S20: =L19 -> 30720
A21: =H39 -> (k) | C21: =C20 -> = | D21: =L40 -> 12650 | F21: =-K39 -> -12650 | H21: (e) | I21: Cash | K21: 64300 | N21: Property Plant and Equipment (PPE) | O21: 0 | Q21: =H30 -> (h) | R21: =K30 -> 300000 | T21: =O21+R21-S21 -> 300000
A22: Balance @ 31 Dec 2025 | B22: =SUM(B5:B21) -> 831396 | C22: = | D22: =SUM(D5:D21) -> 116350 | E22: + | F22: =SUM(F5:F21) -> 715046 | J22: Accounts Receivable | L22: =K21 -> 64300 | N22: ='TB @ 30 Sept 2025'!A7 -> Accounts Payable | P22: ='TB @ 30 Sept 2025'!C7 -> 23400 | Q22: =H27 -> (g) | R22: =K27 -> 19200 | U22: =P22+SUM(S22:S23)-SUM(R22:R23) -> 16850
Q23: =H39 -> (k) | S23: =L40 -> 12650
A24: Balance Check | B24: =SUM(T6:T21) -> 831396 | D24: =SUM(U22:U26) -> 116350 | F24: =SUM(U27:U36)-SUM(T27:T36) -> 715046 | H24: (f) | I24: Salaries Expense | K24: 22300 | N24: ='TB @ 30 Sept 2025'!A8 -> Unearned Revenue | P24: ='TB @ 30 Sept 2025'!C8 -> 14500 | Q24: =H36 -> (j) | S24: =L37 -> 5000 | U24: =P24+S24-R24 -> 19500
B25: =B22-B24 -> 0 | D25: =D22-D24 -> 0 | F25: =F22-F24 -> 0 | J25: Cash | L25: =K24 -> 22300 | N25: Short Term Notes Payable | P25: 0 | Q25: =H8 -> (b) | S25: =L9 -> 30000 | U25: =P25+S25-R25 -> 30000
N26: ='TB @ 30 Sept 2025'!A9 -> Long-term Debt | P26: ='TB @ 30 Sept 2025'!C9 -> 50000 | U26: =P26+S26-R26 -> 50000
H27: (g) | I27: Accounts Payable | K27: 19200 | N27: ='TB @ 30 Sept 2025'!A10 -> Share Capital - Ordinary Shares | P27: ='TB @ 30 Sept 2025'!C10 -> 200000 | Q27: =Q6 -> (a) | S27: =L6 -> 250000 | U27: =P27+S27-R27 -> 450000
J28: Cash | L28: =K27 -> 19200 | N28: ='TB @ 30 Sept 2025'!A11 -> Share Capital - Preference Shares (cumulative) | P28: ='TB @ 30 Sept 2025'!C11 -> 200000 | U28: =P28+S28-R28 -> 200000
N29: ='TB @ 30 Sept 2025'!A12 -> Retained Earnings (@ 31 Dec 2024) | P29: ='TB @ 30 Sept 2025'!C12 -> 5230 | U29: =P29+S29-R29 -> 5230
H30: (h) | I30: Property Plant and Equipment (PPE) | K30: 300000 | N30: ='TB @ 30 Sept 2025'!A13 -> Sales Revenue | P30: ='TB @ 30 Sept 2025'!C13 -> 212300 | Q30: =Q16 -> (d) | S30: =L16 -> 96000 | U30: =P30+S30-R30 -> 308300
J31: Cash | L31: =K30 -> 300000 | N31: ='TB @ 30 Sept 2025'!A14 -> Cost of Goods Sold | O31: ='TB @ 30 Sept 2025'!B14 -> 80674 | Q31: =Q30 -> (d) | R31: =K18 -> 30720 | T31: =O31+R31-S31 -> 111394
N32: ='TB @ 30 Sept 2025'!A15 -> Rent Expense | O32: ='TB @ 30 Sept 2025'!B15 -> 6600 | T32: =O32+R32-S32 -> 6600
H33: (i) | I33: Marketing Expense | K33: 5500 | N33: ='TB @ 30 Sept 2025'!A16 -> Marketing Expense | O33: ='TB @ 30 Sept 2025'!B16 -> 13000 | Q33: =H33 -> (i) | R33: =K33 -> 5500 | T33: =O33+R33-S33 -> 18500
J34: Cash | L34: =K33 -> 5500 | N34: ='TB @ 30 Sept 2025'!A17 -> Salaries Expense | O34: ='TB @ 30 Sept 2025'!B17 -> 69300 | Q34: =H24 -> (f) | R34: =K24 -> 22300 | T34: =O34+R34-S34 -> 91600
N35: ='TB @ 30 Sept 2025'!A18 -> General Admin Expense | O35: ='TB @ 30 Sept 2025'!B18 -> 7740 | Q35: =H39 -> (k) | R35: =K39 -> 12650 | T35: =O35+R35-S35 -> 20390
H36: (j) | I36: Cash | K36: 5000
J37: Unearned Revenue | L37: =K36 -> 5000 | O37: =SUM(O6:O36) -> 705430 | P37: =SUM(P6:P36) -> 705430 | R37: =SUM(R6:R36) -> 900670 | S37: =SUM(S6:S36) -> 900670 | T37: =SUM(T6:T36) -> 1079880 | U37: =SUM(U6:U36) -> 1079880
H39: (k) | I39: General Admin Expense | K39: 12650
J40: Accounts Payable | L40: =K39 -> 12650
K41: =SUM(K4:K37) -> 888020 | L41: =SUM(L4:L37) -> 888020

Sheet Tutorial 3 Sol
A1: TUTORIAL 3 SOLUTION
A3: Adjusting / Correcting Journal Entries | D3: Debit | E3: Credit
A5: (a) | B5: Rent Expense | D5: =26400/12*3 -> 6600
C6: Prepaid Rent | E6: =D5 -> 6600
A8: (b) | B8: Unearned Revenue | D8: =14500/2 -> 7250
C9: Sales Revenue | E9: =D8 -> 7250
B11: Cost of Goods Sold | D11: 2540
C12: Inventory | E12: =D11 -> 2540
A14: (c) | B14: Interest Expense | D14: 2850
C15: Interest Payable | E15: =D14 -> 2850
A17: (d) | B17: Consulting Fees | D17: =450*4 -> 1800
C18: Consulting Fees Payable | E18: =D17 -> 1800
A20: (e) | B20: Depreciation Expense | D20: 8200
C21: Accumulated Depreciation - Equipment | E21: =D20 -> 8200
A23: (f) | B23: Prepaid Salaries | D23: 2200
C24: Salaries Expense | E24: =D23 -> 2200
A26: (g) | B26: Income Tax Expense | D26: 4200
C27: Taxes Payable | E27: =D26 -> 4200
D28: =SUM(D4:D27) -> 35640 | E28: =SUM(E4:E27) -> 35640

Sheet Tutorial 4 Sol
A1: TUTORIAL 4 SOLUTION
A2: PART (1) | J2: PART (4) | P2: PART (2)
A3: TB Worksheet | C3: Unadjusted Trial Balance @ 31 Dec 2025 | E3: Adjustments/Corrections (from Tutorial 2) | H3: Adjusted Trial Balance @ 31 Dec 2025 | J3: Closing Entries (from part 3) | M3: Post Closing Trial Balance @ 31 Dec 2025 | P3: Hunt3X Coporation | T3: =P3 -> Hunt3X Coporation | AC3: =T3 -> Hunt3X Coporation
C4: Debit | D4: Credit | E4: Ref | F4: Debit | G4: Credit | H4: Debit | I4: Credit | J4: Ref | K4: Debit | L4: Credit | M4: Debit | N4: Credit | P4: Statement of Profit & Loss | T4: Statement of Changes in Equity | AC4: Statement of Financial Position
A5: ='TB @ 30 Sept 2025'!A3 -> Cash | C5: ='Tutorial 2 Sol'!T6 -> 359516 | H5: =C5+F5-G5 -> 359516 | M5: =H5+K5-L5 -> 359516 | P5: For the Year Ended 31 December 2025 | T5: =P5 -> For the Year Ended 31 December 2025 | AC5: As at 31 December 2025
A6: ='TB @ 30 Sept 2025'!A4 -> Accounts Receivable | C6: ='Tutorial 2 Sol'!T16 -> 33800 | H6: =C6+F6-G6 -> 33800 | M6: =H6+K6-L6 -> 33800
A7: ='TB @ 30 Sept 2025'!A5 -> Prepaid Rent | C7: ='Tutorial 2 Sol'!T18 -> 19800 | E7: ='Tutorial 3 Sol'!A5 -> (a) | G7: ='Tutorial 3 Sol'!E6 -> 6600 | H7: =C7+F7-G7 -> 13200 | M7: =H7+K7-L7 -> 13200 | Q7: =A22 -> Sales Revenue | R7: =I22 -> 315550 | U7: Ordinary | W7: Preference | Y7: Retained | AA7: Total | AC7: Assets
A8: Prepaid Salaries | C8: 0 | E8: ='Tutorial 3 Sol'!A23 -> (f) | F8: ='Tutorial 3 Sol'!D23 -> 2200 | H8: =C8+F8-G8 -> 2200 | M8: =H8+K8-L8 -> 2200 | Q8: =A23 -> Cost of Goods Sold | R8: =-H23 -> -113934 | U8: Shares | W8: Shares | Y8: Earnings | AA8: Equity | AC8: Current Assets:
A9: ='TB @ 30 Sept 2025'!A6 -> Inventory | C9: ='Tutorial 2 Sol'!T19 -> 118280 | E9: ='Tutorial 3 Sol'!A8 -> (b) | G9: ='Tutorial 3 Sol'!E12 -> 2540 | H9: =C9+F9-G9 -> 115740 | M9: =H9+K9-L9 -> 115740 | P9: Gross Profit | R9: =SUM(R7:R8) -> 201616 | T9: Beginning Balance | U9: ='TB @ 30 Sept 2025'!C10 -> 200000 | W9: ='TB @ 30 Sept 2025'!C11 -> 200000 | Y9: =I21 -> 5230 | AA9: =SUM(U9:Y9) -> 405230 | AD9: =A5 -> Cash | AE9: =H5 -> 359516
A10: ='Tutorial 2 Sol'!N21 -> Property Plant and Equipment (PPE) | C10: ='Tutorial 2 Sol'!T21 -> 300000 | H10: =C10+F10-G10 -> 300000 | M10: =H10+K10-L10 -> 300000 | Q10: =A24 -> Rent Expense | R10: =-H24 -> -13200 | T10: Shares Issuance | U10: ='Tutorial 2 Sol'!S27 -> 250000 | AA10: =U10 -> 250000 | AD10: =A6 -> Accounts Receivable | AE10: =H6 -> 33800
A11: Accumulated Depreciation - Equipment | D11: 0 | E11: ='Tutorial 3 Sol'!A20 -> (e) | G11: ='Tutorial 3 Sol'!E21 -> 8200 | I11: =D11+G11-F11 -> 8200 | N11: =I11+L11-K11 -> 8200 | Q11: =A25 -> Marketing Expense | R11: =-H25 -> -18500 | T11: Net Income | Y11: =R20 -> 43076 | AA11: =SUM(U11:Y11) -> 43076 | AD11: =A7 -> Prepaid Rent | AE11: =H7 -> 13200
A12: ='TB @ 30 Sept 2025'!A7 -> Accounts Payable | D12: ='Tutorial 2 Sol'!U22 -> 16850 | I12: =D12+G12-F12 -> 16850 | N12: =I12+L12-K12 -> 16850 | Q12: =A26 -> Salaries Expense | R12: =-H26 -> -89400 | T12: Ending Balance | U12: =SUM(U9:U11) -> 450000 | W12: =SUM(W9:W11) -> 200000 | Y12: =SUM(Y9:Y11) -> 48306 | AA12: =SUM(AA9:AA11) -> 698306 | AD12: =A8 -> Prepaid Salaries | AE12: =H8 -> 2200
A13: Unearned Revenue | D13: ='Tutorial 2 Sol'!U24 -> 19500 | E13: ='Tutorial 3 Sol'!A8 -> (b) | F13: ='Tutorial 3 Sol'!D8 -> 7250 | I13: =D13+G13-F13 -> 12250 | N13: =I13+L13-K13 -> 12250 | Q13: =A27 -> General Admin Expense | R13: =-H27 -> -20390 | AD13: =A9 -> Inventory | AE13: =H9 -> 115740
A14: Consulting Fees Payable | D14: 0 | E14: ='Tutorial 3 Sol'!A17 -> (d) | G14: ='Tutorial 3 Sol'!E18 -> 1800 | I14: =D14+G14-F14 -> 1800 | N14: =I14+L14-K14 -> 1800 | Q14: =A28 -> Consulting Fees | R14: =-H28 -> -1800 | AD14: Total Current Assets | AE14: =SUM(AE9:AE13) -> 524456
A15: Interest Payable | D15: 0 | E15: =E30 -> (c) | G15: ='Tutorial 3 Sol'!E15 -> 2850 | I15: =D15+G15-F15 -> 2850 | N15: =I15+L15-K15 -> 2850 | Q15: =A29 -> Depreciation Expense | R15: =-H29 -> -8200 | AC15: Non-current Assets:
A16: Taxes Payable | D16: 0 | E16: ='Tutorial 3 Sol'!A26 -> (g) | G16: ='Tutorial 3 Sol'!E27 -> 4200 | I16: =D16+G16-F16 -> 4200 | N16: =I16+L16-K16 -> 4200 | P16: Operating Income | R16: =SUM(R9:R15) -> 50126 | AD16: Property, Plant & Equipment (PPE) | AE16: =H10-I11 -> 291800
A17: ='Tutorial 2 Sol'!N25 -> Short Term Notes Payable | D17: ='Tutorial 2 Sol'!U25 -> 30000 | I17: =D17+G17-F17 -> 30000 | N17: =I17+L17-K17 -> 30000 | Q17: =A30 -> Interest Expense | R17: =-H30 -> -2850 | AD17: Total Non-current Assets | AE17: =SUM(AE16:AE16) -> 291800
A18: ='TB @ 30 Sept 2025'!A9 -> Long-term Debt | D18: ='Tutorial 2 Sol'!U26 -> 50000 | I18: =D18+G18-F18 -> 50000 | N18: =I18+L18-K18 -> 50000 | P18: Profit Before Tax | R18: =SUM(R16:R17) -> 47276 | AC18: Total Assets | AE18: =AE17+AE14 -> 816256
A19: ='TB @ 30 Sept 2025'!A10 -> Share Capital - Ordinary Shares | D19: ='Tutorial 2 Sol'!U27 -> 450000 | I19: =D19+G19-F19 -> 450000 | N19: =I19+L19-K19 -> 450000 | Q19: =A31 -> Income Tax Expense | R19: =-H31 -> -4200
A20: ='TB @ 30 Sept 2025'!A11 -> Share Capital - Preference Shares (cumulative) | D20: ='Tutorial 2 Sol'!U28 -> 200000 | I20: =D20+G20-F20 -> 200000 | N20: =I20+L20-K20 -> 200000 | P20: Net Income | R20: =SUM(R18:R19) -> 43076 | AC20: Liabilities
A21: ='TB @ 30 Sept 2025'!A12 -> Retained Earnings (@ 31 Dec 2024) | D21: ='Tutorial 2 Sol'!U29 -> 5230 | I21: =D21+G21-F21 -> 5230 | J21: Part 3 | L21: =D47 -> 43076 | N21: =I21+L21-K21 -> 48306 | AC21: Current Liabilities:
A22: ='TB @ 30 Sept 2025'!A13 -> Sales Revenue | D22: ='Tutorial 2 Sol'!U30 -> 308300 | E22: =E13 -> (b) | G22: =F13 -> 7250 | I22: =D22+G22-F22 -> 315550 | J22: Part 3 | K22: =C37 -> 315550 | N22: =I22+L22-K22 -> 0 | P22: Check NI balance with TB | R22: =I22-SUM(H23:H31) -> 43076 | AD22: =A12 -> Accounts Payable | AE22: =I12 -> 16850
A23: ='TB @ 30 Sept 2025'!A14 -> Cost of Goods Sold | C23: ='Tutorial 2 Sol'!T31 -> 111394 | E23: ='Tutorial 3 Sol'!A8 -> (b) | F23: ='Tutorial 3 Sol'!D11 -> 2540 | H23: =C23+F23-G23 -> 113934 | J23: Part 3 | L23: =D38 -> 113934 | M23: =H23+K23-L23 -> 0 | AD23: =A13 -> Unearned Revenue | AE23: =I13 -> 12250
A24: ='TB @ 30 Sept 2025'!A15 -> Rent Expense | C24: ='Tutorial 2 Sol'!T32 -> 6600 | E24: =E7 -> (a) | F24: =G7 -> 6600 | H24: =C24+F24-G24 -> 13200 | J24: Part 3 | L24: =D39 -> 13200 | M24: =H24+K24-L24 -> 0 | AD24: =A14 -> Consulting Fees Payable | AE24: =I14 -> 1800
A25: ='TB @ 30 Sept 2025'!A16 -> Marketing Expense | C25: ='Tutorial 2 Sol'!T33 -> 18500 | H25: =C25+F25-G25 -> 18500 | J25: Part 3 | L25: =D40 -> 18500 | M25: =H25+K25-L25 -> 0 | AD25: =A15 -> Interest Payable | AE25: =I15 -> 2850
A26: ='TB @ 30 Sept 2025'!A17 -> Salaries Expense | C26: ='Tutorial 2 Sol'!T34 -> 91600 | E26: ='Tutorial 3 Sol'!A23 -> (f) | G26: ='Tutorial 3 Sol'!E24 -> 2200 | H26: =C26+F26-G26 -> 89400 | J26: Part 3 | L26: =D41 -> 89400 | M26: =H26+K26-L26 -> 0 | AD26: =A16 -> Taxes Payable | AE26: =I16 -> 4200
A27: ='Tutorial 2 Sol'!N35 -> General Admin Expense | C27: ='Tutorial 2 Sol'!T35 -> 20390 | H27: =C27+F27-G27 -> 20390 | J27: Part 3 | L27: =D42 -> 20390 | M27: =H27+K27-L27 -> 0 | AD27: ST Notes Payable | AE27: =N17 -> 30000
A28: Consulting Fees | C28: 0 | E28: ='Tutorial 3 Sol'!A17 -> (d) | F28: ='Tutorial 3 Sol'!D17 -> 1800 | H28: =C28+F28-G28 -> 1800 | J28: Part 3 | L28: =D43 -> 1800 | M28: =H28+K28-L28 -> 0 | AD28: Total Current Liabilities | AE28: =SUM(AE22:AE27) -> 67950
A29: Depreciation Expense | C29: 0 | E29: ='Tutorial 3 Sol'!A20 -> (e) | F29: ='Tutorial 3 Sol'!D20 -> 8200 | H29: =C29+F29-G29 -> 8200 | J29: Part 3 | L29: =D44 -> 8200 | M29: =H29+K29-L29 -> 0 | AC29: Non-current Liabilities:
A30: Interest Expense | C30: 0 | E30: ='Tutorial 3 Sol'!A14 -> (c) | F30: ='Tutorial 3 Sol'!D14 -> 2850 | H30: =C30+F30-G30 -> 2850 | J30: Part 3 | L30: =D45 -> 2850 | M30: =H30+K30-L30 -> 0 | AD30: =A18 -> Long-term Debt | AE30: =I18 -> 50000
A31: Income Tax Expense | C31: 0 | E31: ='Tutorial 3 Sol'!A26 -> (g) | F31: ='Tutorial 3 Sol'!D26 -> 4200 | H31: =C31+F31-G31 -> 4200 | J31: Part 3 | L31: =D46 -> 4200 | M31: =H31+K31-L31 -> 0 | AD31: Total Non-current Liabilities | AE31: =AE30 -> 50000
C32: =SUM(C5:C31) -> 1079880 | D32: =SUM(D5:D31) -> 1079880 | F32: =SUM(F5:F31) -> 35640 | G32: =SUM(G5:G31) -> 35640 | H32: =SUM(H5:H31) -> 1096930 | I32: =SUM(I5:I31) -> 1096930 | K32: =SUM(K5:K31) -> 315550 | L32: =SUM(L5:L31) -> 315550 | M32: =SUM(M5:M31) -> 824456 | N32: =SUM(N5:N31) -> 824456 | AC32: Total Liabilities | AE32: =AE28+AE31 -> 117950
D33: =C32-D32 -> 0 | I33: =H32-I32 -> 0 | N33: =M32-N32 -> 0 | AC33: Equity
AC34: =A19 -> Share Capital - Ordinary Shares | AE34: =U12 -> 450000
A35: PART (3) | AC35: =A20 -> Share Capital - Preference Shares (cumulative) | AE35: =W12 -> 200000
A36: Closing Entries @ 31 December 2025 | AC36: Retained Earnings | AE36: =Y12 -> 48306
A37: =A22 -> Sales Revenue | C37: =I22 -> 315550 | AC37: Total Equity | AE37: =SUM(AE34:AE36) -> 698306
B38: =A23 -> Cost of Goods Sold | D38: =H23 -> 113934 | AC38: Total Liabilities & Equity | AE38: =AE37+AE32 -> 816256
B39: =A24 -> Rent Expense | D39: =H24 -> 13200
B40: =A25 -> Marketing Expense | D40: =H25 -> 18500
...

Sheet TB @ 31 Dec 2024
A1: Hunt3X Corporation
A2: Account Balances as at 31 Dec 2024 | B2: Debit | C2: Credit
A3: ='TB @ 30 Sept 2025'!A3 -> Cash | B3: 350130
A4: ='TB @ 30 Sept 2025'!A4 -> Accounts Receivable | B4: 21700
A5: ='TB @ 30 Sept 2025'!A6 -> Inventory | B5: 102000
A6: ='TB @ 30 Sept 2025'!A7 -> Accounts Payable | C6: 18600
A7: ='TB @ 30 Sept 2025'!A9 -> Long-term Debt | C7: ='TB @ 30 Sept 2025'!C9 -> 50000
A8: ='TB @ 30 Sept 2025'!A10 -> Share Capital - Ordinary Shares | C8: ='TB @ 30 Sept 2025'!C10 -> 200000
A9: ='TB @ 30 Sept 2025'!A11 -> Share Capital - Preference Shares (cumulative) | C9: ='TB @ 30 Sept 2025'!C11 -> 200000
A10: ='TB @ 30 Sept 2025'!A12 -> Retained Earnings (@ 31 Dec 2024) | C10: ='TB @ 30 Sept 2025'!C12 -> 5230
B11: =SUM(B3:B10) -> 473830 | C11: =SUM(C3:C10) -> 473830
A13: Total Assets | B13: =SUM(B3:B5) -> 473830
A14: Total Liabilities | C14: =SUM(C6:C7) -> 68600
A15: Total Equity | C15: =SUM(C8:C10) -> 405230
